<?xml version="1.0" ?>
<!-- =================================================================================== -->
<!-- |    This document was autogenerated by xacro from core/robot_simulation/urdf/fishrot/fishbot.xacro | -->
<!-- |    EDITING THIS FILE BY HAND IS NOT RECOMMENDED                                 | -->
<!-- =================================================================================== -->
<robot name="fishbot">
  <!-- 机器人的身体部件 -->
  <link name="base_link">
    <!-- 部件的外观描述 -->
    <visual>
      <!-- 相对于它所属 link 原点的位置偏移 -->
      <origin rpy="0 0 0" xyz="0 0 0"/>
      <!-- 几何形状 -->
      <geometry>
        <box size="0.5 0.5 0.1"/>
        <!-- 长lengthm 宽widthm 高heightm -->
      </geometry>
      <!-- 材质颜色 -->
      <material name="red">
        <color rgba="1 0 0 0.2"/>
        <!-- 红 绿 蓝 透明度，范围0~1 -->
      </material>
    </visual>
    <!-- 碰撞体积 (与visual几何一致) -->
    <collision>
      <origin rpy="0 0 0" xyz="0 0 0"/>
      <geometry>
        <box size="0.5 0.5 0.1"/>
      </geometry>
    </collision>
    <!-- 惯性 (质量与转动惯量，Gazebo仿真必需) -->
    <inertial>
      <mass value="5"/>
      <!-- 长方体转动惯量: Ixx=m/12*(y²+z²), Iyy=m/12*(x²+z²), Izz=m/12*(x²+y²) -->
      <inertia ixx="0.10833333333333334" ixy="0" ixz="0" iyy="0.10833333333333334" iyz="0" izz="0.20833333333333334"/>
    </inertial>
  </link>
  <!-- 添加虚拟部件，使机器人轮子贴合地面 -->
  <link name="base_footprint"/>
  <joint name="base_footprint_joint" type="fixed">
    <parent link="base_footprint"/>
    <child link="base_link"/>
    <origin rpy="0 0 0" xyz="0 0 0.112"/>
    <!-- base_link 在 base_footprint 上方 0.112m，轮子恰好贴地 -->
  </joint>
  <!-- 机器人的IMU部件 -->
  <link name="imu_link">
    <!-- 部件的外观描述 -->
    <visual>
      <!-- 相对于它所属 link 原点的位置偏移 -->
      <origin rpy="0 0 0" xyz="0 0 0"/>
      <!-- 几何形状 -->
      <geometry>
        <box size="0.02 0.02 0.02"/>
        <!-- 长0.02m 宽0.02m 高0.02m -->
      </geometry>
      <!-- 材质颜色 -->
      <material name="gray">
        <color rgba="0 0 0 0.5"/>
      </material>
    </visual>
    <!-- 碰撞体积 (与visual几何一致) -->
    <collision>
      <origin rpy="0 0 0" xyz="0 0 0"/>
      <geometry>
        <box size="0.02 0.02 0.02"/>
      </geometry>
    </collision>
    <!-- 惯性 (质量与转动惯量，Gazebo仿真必需) -->
    <inertial>
      <mass value="0.01"/>
      <inertia ixx="0.000000667" ixy="0" ixz="0" iyy="0.000000667" iyz="0" izz="0.000000667"/>
    </inertial>
  </link>
  <!-- 将IMU部件固定到机器人身体部件 -->
  <joint name="imu_link_joint" type="fixed">
    <parent link="base_link"/>
    <child link="imu_link"/>
    <origin rpy="0 0 0" xyz="0 0 -0.1"/>
    <!-- child(imu_link) 相对于 parent(base_link) 的偏移 -->
  </joint>
  <!-- 雷达支撑杆部件 -->
  <link name="laser_cylinder_link">
    <!-- 部件的外观描述 -->
    <visual>
      <!-- 相对于它所属 link 原点的位置偏移 -->
      <origin rpy="0 0 0" xyz="0 0 0"/>
      <!-- 几何形状 -->
      <geometry>
        <cylinder length="0.1" radius="0.01"/>
        <!-- 圆柱体：半径0.01m 高0.1m -->
      </geometry>
      <!-- 材质颜色 -->
      <material name="black">
        <color rgba="0 0 0 1.0"/>
      </material>
    </visual>
    <!-- 碰撞体积 (与visual几何一致) -->
    <collision>
      <origin rpy="0 0 0" xyz="0 0 0"/>
      <geometry>
        <cylinder length="0.1" radius="0.01"/>
      </geometry>
    </collision>
    <!-- 惯性 (质量与转动惯量，Gazebo仿真必需) -->
    <inertial>
      <mass value="0.1"/>
      <inertia ixx="0.0000858" ixy="0" ixz="0" iyy="0.000005" iyz="0" izz="0.0000858"/>
    </inertial>
  </link>
  <!-- 雷达部件 -->
  <link name="laser_link">
    <!-- 部件的外观描述 -->
    <visual>
      <!-- 相对于它所属 link 原点的位置偏移 -->
      <origin rpy="0 0 0" xyz="0 0 0"/>
      <!-- 几何形状 -->
      <geometry>
        <cylinder length="0.2" radius="0.02"/>
        <!-- 圆柱体：半径0.02m 高0.2m -->
      </geometry>
      <!-- 材质颜色 -->
      <material name="black">
        <color rgba="0 0 0 1.0"/>
      </material>
    </visual>
    <!-- 碰撞体积 (与visual几何一致) -->
    <collision>
      <origin rpy="0 0 0" xyz="0 0 0"/>
      <geometry>
        <cylinder length="0.2" radius="0.02"/>
      </geometry>
    </collision>
    <!-- 惯性 (质量与转动惯量，Gazebo仿真必需) -->
    <inertial>
      <mass value="0.2"/>
      <inertia ixx="0.000687" ixy="0" ixz="0" iyy="0.00004" iyz="0" izz="0.000687"/>
    </inertial>
  </link>
  <!-- 将雷达固定到支撑杆 -->
  <joint name="laser_joint" type="fixed">
    <parent link="laser_cylinder_link"/>
    <child link="laser_link"/>
    <origin rpy="0 0 0" xyz="0 0 0.05"/>
    <!-- child(laser_link) 相对于 parent(laser_cylinder_link) 的偏移 -->
  </joint>
  <!-- 将雷达支撑杆固定到机器人身体 -->
  <joint name="laser_cylinder_joint" type="fixed">
    <parent link="base_link"/>
    <child link="laser_cylinder_link"/>
    <origin rpy="0 0 0" xyz="0 0 0.1"/>
    <!-- child(laser_cylinder_link) 相对于 parent(base_link) 的偏移 -->
  </joint>
  <gazebo reference="laser_cylinder_link">
    <visual>
      <material>
        <ambient>0 0 1 1</ambient>
        <diffuse>0 0 1 1</diffuse>
        <specular>0.1 0.1 0.1 1</specular>
        <emissive>0 0 0 1</emissive>
      </material>
    </visual>
  </gazebo>
  <gazebo reference="laser_link">
    <visual>
      <material>
        <ambient>0 0 1 1</ambient>
        <diffuse>0 0 1 1</diffuse>
        <specular>0.1 0.1 0.1 1</specular>
        <emissive>0 0 0 1</emissive>
      </material>
    </visual>
  </gazebo>
  <link name="left_front_wheel_link">
    <!-- 部件的外观描述 -->
    <visual>
      <!-- 相对于它所属 link 原点的位置偏移 -->
      <!-- 1.5708弧度，表示绕X轴旋转90度，把竖直的圆柱体放平成轮子 -->
      <origin rpy="1.5708 0 0" xyz="0 0 0"/>
      <!-- 几何形状 -->
      <geometry>
        <cylinder length="0.04" radius="0.032"/>
        <!-- 半径0.032m 高0.04m -->
      </geometry>
      <!-- 材质颜色 -->
      <material name="yellow">
        <color rgba="1 1 0 0.8"/>
        <!-- 红 绿 蓝 透明度，范围0~1 -->
      </material>
    </visual>
    <!-- 碰撞体积 (与visual几何一致) -->
    <collision>
      <origin rpy="1.5708 0 0" xyz="0 0 0"/>
      <geometry>
        <cylinder length="0.04" radius="0.032"/>
      </geometry>
    </collision>
    <!-- 惯性 (质量与转动惯量，Gazebo仿真必需) -->
    <inertial>
      <mass value="0.1"/>
      <!-- 圆柱体转动惯量 (半径r=0.032, 长l=0.04, 绕轴I=mr²/2, 垂直轴I=m(3r²+l²)/12) -->
      <inertia ixx="0.0000389" ixy="0" ixz="0" iyy="0.0000512" iyz="0" izz="0.0000389"/>
    </inertial>
  </link>
  <joint name="left_front_wheel_joint" type="continuous">
    <parent link="base_link"/>
    <child link="left_front_wheel_link"/>
    <origin rpy="0 0 0" xyz=" 0.25  0.25 -0.08"/>
    <!-- child(${${wheel_name}_link) 相对于 parent(base_link) 的偏移 -->
    <axis xyz="0 1 0"/>
    <!-- 轴向为y轴 -->
  </joint>
  <!-- Gazebo Fortress 驱动轮接触物理参数，防打滑陷地 -->
  <gazebo reference="left_front_wheel_link">
    <collision>
      <surface>
        <contact>
          <ode>
            <mu>20.0</mu>
            <!-- 滚动方向摩擦系数，越大越不打滑 -->
            <mu2>20.0</mu2>
            <!-- 横向侧滑摩擦系数 -->
            <kp>10000000000.0</kp>
            <!-- 接触刚度，轮子硬度 -->
            <kd>1.0</kd>
            <!-- 接触阻尼，落地缓冲 -->
          </ode>
        </contact>
      </surface>
    </collision>
  </gazebo>
  <link name="right_front_wheel_link">
    <!-- 部件的外观描述 -->
    <visual>
      <!-- 相对于它所属 link 原点的位置偏移 -->
      <!-- 1.5708弧度，表示绕X轴旋转90度，把竖直的圆柱体放平成轮子 -->
      <origin rpy="1.5708 0 0" xyz="0 0 0"/>
      <!-- 几何形状 -->
      <geometry>
        <cylinder length="0.04" radius="0.032"/>
        <!-- 半径0.032m 高0.04m -->
      </geometry>
      <!-- 材质颜色 -->
      <material name="yellow">
        <color rgba="1 1 0 0.8"/>
        <!-- 红 绿 蓝 透明度，范围0~1 -->
      </material>
    </visual>
    <!-- 碰撞体积 (与visual几何一致) -->
    <collision>
      <origin rpy="1.5708 0 0" xyz="0 0 0"/>
      <geometry>
        <cylinder length="0.04" radius="0.032"/>
      </geometry>
    </collision>
    <!-- 惯性 (质量与转动惯量，Gazebo仿真必需) -->
    <inertial>
      <mass value="0.1"/>
      <!-- 圆柱体转动惯量 (半径r=0.032, 长l=0.04, 绕轴I=mr²/2, 垂直轴I=m(3r²+l²)/12) -->
      <inertia ixx="0.0000389" ixy="0" ixz="0" iyy="0.0000512" iyz="0" izz="0.0000389"/>
    </inertial>
  </link>
  <joint name="right_front_wheel_joint" type="continuous">
    <parent link="base_link"/>
    <child link="right_front_wheel_link"/>
    <origin rpy="0 0 0" xyz=" 0.25 -0.25 -0.08"/>
    <!-- child(${${wheel_name}_link) 相对于 parent(base_link) 的偏移 -->
    <axis xyz="0 1 0"/>
    <!-- 轴向为y轴 -->
  </joint>
  <!-- Gazebo Fortress 驱动轮接触物理参数，防打滑陷地 -->
  <gazebo reference="right_front_wheel_link">
    <collision>
      <surface>
        <contact>
          <ode>
            <mu>20.0</mu>
            <!-- 滚动方向摩擦系数，越大越不打滑 -->
            <mu2>20.0</mu2>
            <!-- 横向侧滑摩擦系数 -->
            <kp>10000000000.0</kp>
            <!-- 接触刚度，轮子硬度 -->
            <kd>1.0</kd>
            <!-- 接触阻尼，落地缓冲 -->
          </ode>
        </contact>
      </surface>
    </collision>
  </gazebo>
  <link name="left_rear_wheel_link">
    <!-- 部件的外观描述 -->
    <visual>
      <!-- 相对于它所属 link 原点的位置偏移 -->
      <!-- 1.5708弧度，表示绕X轴旋转90度，把竖直的圆柱体放平成轮子 -->
      <origin rpy="1.5708 0 0" xyz="0 0 0"/>
      <!-- 几何形状 -->
      <geometry>
        <cylinder length="0.04" radius="0.032"/>
        <!-- 半径0.032m 高0.04m -->
      </geometry>
      <!-- 材质颜色 -->
      <material name="yellow">
        <color rgba="1 1 0 0.8"/>
        <!-- 红 绿 蓝 透明度，范围0~1 -->
      </material>
    </visual>
    <!-- 碰撞体积 (与visual几何一致) -->
    <collision>
      <origin rpy="1.5708 0 0" xyz="0 0 0"/>
      <geometry>
        <cylinder length="0.04" radius="0.032"/>
      </geometry>
    </collision>
    <!-- 惯性 (质量与转动惯量，Gazebo仿真必需) -->
    <inertial>
      <mass value="0.1"/>
      <!-- 圆柱体转动惯量 (半径r=0.032, 长l=0.04, 绕轴I=mr²/2, 垂直轴I=m(3r²+l²)/12) -->
      <inertia ixx="0.0000389" ixy="0" ixz="0" iyy="0.0000512" iyz="0" izz="0.0000389"/>
    </inertial>
  </link>
  <joint name="left_rear_wheel_joint" type="continuous">
    <parent link="base_link"/>
    <child link="left_rear_wheel_link"/>
    <origin rpy="0 0 0" xyz="-0.25  0.25 -0.08"/>
    <!-- child(${${wheel_name}_link) 相对于 parent(base_link) 的偏移 -->
    <axis xyz="0 1 0"/>
    <!-- 轴向为y轴 -->
  </joint>
  <!-- Gazebo Fortress 驱动轮接触物理参数，防打滑陷地 -->
  <gazebo reference="left_rear_wheel_link">
    <collision>
      <surface>
        <contact>
          <ode>
            <mu>20.0</mu>
            <!-- 滚动方向摩擦系数，越大越不打滑 -->
            <mu2>20.0</mu2>
            <!-- 横向侧滑摩擦系数 -->
            <kp>10000000000.0</kp>
            <!-- 接触刚度，轮子硬度 -->
            <kd>1.0</kd>
            <!-- 接触阻尼，落地缓冲 -->
          </ode>
        </contact>
      </surface>
    </collision>
  </gazebo>
  <link name="right_rear_wheel_link">
    <!-- 部件的外观描述 -->
    <visual>
      <!-- 相对于它所属 link 原点的位置偏移 -->
      <!-- 1.5708弧度，表示绕X轴旋转90度，把竖直的圆柱体放平成轮子 -->
      <origin rpy="1.5708 0 0" xyz="0 0 0"/>
      <!-- 几何形状 -->
      <geometry>
        <cylinder length="0.04" radius="0.032"/>
        <!-- 半径0.032m 高0.04m -->
      </geometry>
      <!-- 材质颜色 -->
      <material name="yellow">
        <color rgba="1 1 0 0.8"/>
        <!-- 红 绿 蓝 透明度，范围0~1 -->
      </material>
    </visual>
    <!-- 碰撞体积 (与visual几何一致) -->
    <collision>
      <origin rpy="1.5708 0 0" xyz="0 0 0"/>
      <geometry>
        <cylinder length="0.04" radius="0.032"/>
      </geometry>
    </collision>
    <!-- 惯性 (质量与转动惯量，Gazebo仿真必需) -->
    <inertial>
      <mass value="0.1"/>
      <!-- 圆柱体转动惯量 (半径r=0.032, 长l=0.04, 绕轴I=mr²/2, 垂直轴I=m(3r²+l²)/12) -->
      <inertia ixx="0.0000389" ixy="0" ixz="0" iyy="0.0000512" iyz="0" izz="0.0000389"/>
    </inertial>
  </link>
  <joint name="right_rear_wheel_joint" type="continuous">
    <parent link="base_link"/>
    <child link="right_rear_wheel_link"/>
    <origin rpy="0 0 0" xyz="-0.25 -0.25 -0.08"/>
    <!-- child(${${wheel_name}_link) 相对于 parent(base_link) 的偏移 -->
    <axis xyz="0 1 0"/>
    <!-- 轴向为y轴 -->
  </joint>
  <!-- Gazebo Fortress 驱动轮接触物理参数，防打滑陷地 -->
  <gazebo reference="right_rear_wheel_link">
    <collision>
      <surface>
        <contact>
          <ode>
            <mu>20.0</mu>
            <!-- 滚动方向摩擦系数，越大越不打滑 -->
            <mu2>20.0</mu2>
            <!-- 横向侧滑摩擦系数 -->
            <kp>10000000000.0</kp>
            <!-- 接触刚度，轮子硬度 -->
            <kd>1.0</kd>
            <!-- 接触阻尼，落地缓冲 -->
          </ode>
        </contact>
      </surface>
    </collision>
  </gazebo>
  <link name="center_caster_link">
    <!-- 部件的外观描述 -->
    <visual>
      <!-- 相对于它所属 link 原点的位置偏移 -->
      <origin rpy="0 0 0" xyz="0 0 0"/>
      <!-- 几何形状 -->
      <geometry>
        <sphere radius="0.016"/>
        <!-- 半径0.016m -->
      </geometry>
      <!-- 材质颜色 -->
      <material name="yellow">
        <color rgba="1 1 0 0.8"/>
        <!-- 红 绿 蓝 透明度，范围0~1 -->
      </material>
    </visual>
    <!-- 碰撞体积 (与visual几何一致) -->
    <collision>
      <origin rpy="0 0 0" xyz="0 0 0"/>
      <geometry>
        <sphere radius="0.016"/>
      </geometry>
    </collision>
    <!-- 惯性 (质量与转动惯量，Gazebo仿真必需) -->
    <inertial>
      <mass value="0.05"/>
      <!-- 球体转动惯量: I = 2/5 * m * r² -->
      <inertia ixx="0.00000512" ixy="0" ixz="0" iyy="0.00000512" iyz="0" izz="0.00000512"/>
    </inertial>
  </link>
  <joint name="center_caster_joint" type="fixed">
    <parent link="base_link"/>
    <child link="center_caster_link"/>
    <origin rpy="0 0 0" xyz="0 0 -0.096"/>
    <!-- child(${${wheel_name}_link) 相对于 parent(base_link) 的偏移 -->
  </joint>
  <!-- Gazebo Fortress 万向轮接触物理参数，无摩擦可自由滑动 -->
  <gazebo reference="center_caster_link">
    <collision>
      <surface>
        <contact>
          <ode>
            <mu>0.0</mu>
            <!-- 滚动摩擦为0，万向轮无阻力 -->
            <mu2>0.0</mu2>
            <!-- 侧滑摩擦为0，万向轮可自由转向 -->
            <kp>10000000000.0</kp>
            <!-- 接触刚度，避免陷地 -->
            <kd>1.0</kd>
            <!-- 接触阻尼，落地缓冲 -->
          </ode>
        </contact>
      </surface>
    </collision>
  </gazebo>
  <!-- 中心万向轮 -->
  <!-- 差速驱动插件（作用在整个模型上） -->
  <gazebo>
    <plugin filename="libignition-gazebo-diff-drive-system.so" name="ignition::gazebo::systems::DiffDrive">
      <left_joint>left_front_wheel_joint</left_joint>
      <left_joint>left_rear_wheel_joint</left_joint>
      <right_joint>right_front_wheel_joint</right_joint>
      <right_joint>right_rear_wheel_joint</right_joint>
      <wheel_separation>0.5</wheel_separation>
      <wheel_radius>0.032</wheel_radius>
      <odom_publish_frequency>30</odom_publish_frequency>
      <topic>cmd_vel</topic>
    </plugin>
  </gazebo>
</robot>
